Workbook

Sheet Paper_Table
A1: Dataset | B1: Strongest baseline | C1: SRC-v16c | D1: Gain (pp) | E1: Baseline method | F1: n
A2: =Compact_Summary!A2 -> amazon-computers | B2: =Compact_Summary!B2&" "&TEXT(Compact_Summary!F2,"0.00")&" ± "&TEXT(Compact_Summary!G2,"0.00") -> GraphSAGE 77.46 ± 1.87 | C2: ="SRC-v16c "&TEXT(Compact_Summary!K2,"0.00")&" ± "&TEXT(Compact_Summary!L2,"0.00") -> SRC-v16c 78.71 ± 1.15 | D2: =Compact_Summary!M2 -> 1.2511326 | E2: =Compact_Summary!B2 -> GraphSAGE | F2: =Compact_Summary!H2 -> 10
A3: =Compact_Summary!A3 -> amazon-photo | B3: =Compact_Summary!B3&" "&TEXT(Compact_Summary!F3,"0.00")&" ± "&TEXT(Compact_Summary!G3,"0.00") -> GraphSAGE 87.59 ± 1.33 | C3: ="SRC-v16c "&TEXT(Compact_Summary!K3,"0.00")&" ± "&TEXT(Compact_Summary!L3,"0.00") -> SRC-v16c 88.76 ± 1.35 | D3: =Compact_Summary!M3 -> 1.173792 | E3: =Compact_Summary!B3 -> GraphSAGE | F3: =Compact_Summary!H3 -> 10
A4: =Compact_Summary!A4 -> chameleon | B4: =Compact_Summary!B4&" "&TEXT(Compact_Summary!F4,"0.00")&" ± "&TEXT(Compact_Summary!G4,"0.00") -> LINKX 71.25 ± 1.49 | C4: ="SRC-v16c "&TEXT(Compact_Summary!K4,"0.00")&" ± "&TEXT(Compact_Summary!L4,"0.00") -> SRC-v16c 72.48 ± 1.85 | D4: =Compact_Summary!M4 -> 1.2280708 | E4: =Compact_Summary!B4 -> LINKX | F4: =Compact_Summary!H4 -> 10
A5: =Compact_Summary!A5 -> cornell | B5: =Compact_Summary!B5&" "&TEXT(Compact_Summary!F5,"0.00")&" ± "&TEXT(Compact_Summary!G5,"0.00") -> GraphSAGE 70.27 ± 5.70 | C5: ="SRC-v16c "&TEXT(Compact_Summary!K5,"0.00")&" ± "&TEXT(Compact_Summary!L5,"0.00") -> SRC-v16c 75.41 ± 7.26 | D5: =Compact_Summary!M5 -> 5.1351359 | E5: =Compact_Summary!B5 -> GraphSAGE | F5: =Compact_Summary!H5 -> 10
A6: =Compact_Summary!A6 -> texas | B6: =Compact_Summary!B6&" "&TEXT(Compact_Summary!F6,"0.00")&" ± "&TEXT(Compact_Summary!G6,"0.00") -> GraphSAGE 78.38 ± 7.96 | C6: ="SRC-v16c "&TEXT(Compact_Summary!K6,"0.00")&" ± "&TEXT(Compact_Summary!L6,"0.00") -> SRC-v16c 86.32 ± 4.08 | D6: =Compact_Summary!M6 -> 7.9374113 | E6: =Compact_Summary!B6 -> GraphSAGE | F6: =Compact_Summary!H6 -> 10
A7: =Compact_Summary!A7 -> wisconsin | B7: =Compact_Summary!B7&" "&TEXT(Compact_Summary!F7,"0.00")&" ± "&TEXT(Compact_Summary!G7,"0.00") -> GraphSAGE 81.96 ± 3.18 | C7: ="SRC-v16c "&TEXT(Compact_Summary!K7,"0.00")&" ± "&TEXT(Compact_Summary!L7,"0.00") -> SRC-v16c 84.31 ± 4.24 | D7: =Compact_Summary!M7 -> 2.3529401 | E7: =Compact_Summary!B7 -> GraphSAGE | F7: =Compact_Summary!H7 -> 10
A9: Average | B9: =Compact_Summary!F9 -> 77.817356 | C9: =Compact_Summary!K9 -> 80.997103 | D9: =Compact_Summary!M9 -> 3.1797471

Sheet Raw_SRC_V16C_Repeats
A1: dataset | B1: repeat | C1: seed | D1: split_id | E1: split_policy | F1: train_acc_raw | G1: val_acc_raw | H1: test_acc_raw | I1: val_bal_acc_raw | J1: top_k | K1: dim | L1: energy | M1: alphas | N1: w | O1: feature_variant | P1: selection_rule | Q1: grid | R1: source_file | S1: source_line | T1: source_path
A2: amazon-computers | B2: 0 | C2: 20260419 | E2: class_balanced_random_20_train_30_val_per_class | F2: 1 | G2: 0.85333333 | H2: 0.77618473 | I2: 0.85333333 | J2: 4000 | K2: 64 | L2: 0.95 | M2: (0.05, 0.5, 5.0) | N2: 0.6 | O2: full | P2: grid_selected_by_val_only_no_test | Q2: fast | R2: src_v16c_final_6datasets_repeat_rows.csv | S2: 42 | T2: /mnt/data/srcv16c_submission_package/src_v16c_final_6datasets_repeat_rows.csv
A3: amazon-computers | B3: 1 | C3: 20260420 | E3: class_balanced_random_20_train_30_val_per_class | F3: 1 | G3: 0.86666667 | H3: 0.80485964 | I3: 0.86666667 | J3: 4000 | K3: 64 | L3: 0.95 | M3: (0.01, 0.1, 1.0) | N3: 0.4 | O3: full | P3: grid_selected_by_val_only_no_test | Q3: fast | R3: src_v16c_final_6datasets_repeat_rows.csv | S3: 43 | T3: /mnt/data/srcv16c_submission_package/src_v16c_final_6datasets_repeat_rows.csv
A4: amazon-computers | B4: 2 | C4: 20260421 | E4: class_balanced_random_20_train_30_val_per_class | F4: 1 | G4: 0.84333333 | H4: 0.7741473 | I4: 0.84333333 | J4: 4000 | K4: 64 | L4: 0.99 | M4: (0.05, 0.5, 5.0) | N4: 0.6 | O4: full | P4: grid_selected_by_val_only_no_test | Q4: fast | R4: src_v16c_final_6datasets_repeat_rows.csv | S4: 44 | T4: /mnt/data/srcv16c_submission_package/src_v16c_final_6datasets_repeat_rows.csv
A5: amazon-computers | B5: 3 | C5: 20260422 | E5: class_balanced_random_20_train_30_val_per_class | F5: 1 | G5: 0.86 | H5: 0.79603079 | I5: 0.86 | J5: 4000 | K5: 64 | L5: 0.95 | M5: (0.01, 0.1, 1.0) | N5: 0.6 | O5: full | P5: grid_selected_by_val_only_no_test | Q5: fast | R5: src_v16c_final_6datasets_repeat_rows.csv | S5: 45 | T5: /mnt/data/srcv16c_submission_package/src_v16c_final_6datasets_repeat_rows.csv
A6: amazon-computers | B6: 4 | C6: 20260423 | E6: class_balanced_random_20_train_30_val_per_class | F6: 1 | G6: 0.86 | H6: 0.79022034 | I6: 0.86 | J6: 4000 | K6: 64 | L6: 0.95 | M6: (0.01, 0.1, 1.0) | N6: 0.4 | O6: full | P6: grid_selected_by_val_only_no_test | Q6: fast | R6: src_v16c_final_6datasets_repeat_rows.csv | S6: 46 | T6: /mnt/data/srcv16c_submission_package/src_v16c_final_6datasets_repeat_rows.csv
A7: amazon-computers | B7: 5 | C7: 20260424 | E7: class_balanced_random_20_train_30_val_per_class | F7: 1 | G7: 0.84666667 | H7: 0.79014488 | I7: 0.84666667 | J7: 4000 | K7: 64 | L7: 0.95 | M7: (0.01, 0.1, 1.0) | N7: 0.4 | O7: full | P7: grid_selected_by_val_only_no_test | Q7: fast | R7: src_v16c_final_6datasets_repeat_rows.csv | S7: 47 | T7: /mnt/data/srcv16c_submission_package/src_v16c_final_6datasets_repeat_rows.csv
A8: amazon-computers | B8: 6 | C8: 20260425 | E8: class_balanced_random_20_train_30_val_per_class | F8: 1 | G8: 0.86 | H8: 0.78773015 | I8: 0.86 | J8: 4000 | K8: 64 | L8: 0.95 | M8: (0.01, 0.1, 1.0) | N8: 0.4 | O8: full | P8: grid_selected_by_val_only_no_test | Q8: fast | R8: src_v16c_final_6datasets_repeat_rows.csv | S8: 48 | T8: /mnt/data/srcv16c_submission_package/src_v16c_final_6datasets_repeat_rows.csv
A9: amazon-computers | B9: 7 | C9: 20260426 | E9: class_balanced_random_20_train_30_val_per_class | F9: 1 | G9: 0.85333333 | H9: 0.80116209 | I9: 0.85333333 | J9: 4000 | K9: 64 | L9: 0.95 | M9: (0.01, 0.1, 1.0) | N9: 0.4 | O9: full | P9: grid_selected_by_val_only_no_test | Q9: fast | R9: src_v16c_final_6datasets_repeat_rows.csv | S9: 49 | T9: /mnt/data/srcv16c_submission_package/src_v16c_final_6datasets_repeat_rows.csv
A10: amazon-computers | B10: 8 | C10: 20260427 | E10: class_balanced_random_20_train_30_val_per_class | F10: 1 | G10: 0.87333333 | H10: 0.77210987 | I10: 0.87333333 | J10: 4000 | K10: 64 | L10: 0.95 | M10: (0.01, 0.1, 1.0) | N10: 0.6 | O10: full | P10: grid_selected_by_val_only_no_test | Q10: fast | R10: src_v16c_final_6datasets_repeat_rows.csv | S10: 50 | T10: /mnt/data/srcv16c_submission_package/src_v16c_final_6datasets_repeat_rows.csv
A11: amazon-computers | B11: 9 | C11: 20260428 | E11: class_balanced_random_20_train_30_val_per_class | F11: 1 | G11: 0.83 | H11: 0.77837308 | I11: 0.83 | J11: 4000 | K11: 64 | L11: 0.95 | M11: (0.01, 0.1, 1.0) | N11: 0.6 | O11: full | P11: grid_selected_by_val_only_no_test | Q11: fast | R11: src_v16c_final_6datasets_repeat_rows.csv | S11: 51 | T11: /mnt/data/srcv16c_submission_package/src_v16c_final_6datasets_repeat_rows.csv
A12: amazon-photo | B12: 0 | C12: 20260419 | E12: class_balanced_random_20_train_30_val_per_class | F12: 1 | G12: 0.925 | H12: 0.88675862 | I12: 0.925 | J12: 4000 | K12: 32 | L12: 0.9 | M12: (0.01, 0.1, 1.0) | N12: 0.4 | O12: full | P12: grid_selected_by_val_only_no_test | Q12: default | R12: src_v16c_final_6datasets_repeat_rows.csv | S12: 32 | T12: /mnt/data/srcv16c_submission_package/src_v16c_final_6datasets_repeat_rows.csv
A13: amazon-photo | B13: 1 | C13: 20260420 | E13: class_balanced_random_20_train_30_val_per_class | F13: 1 | G13: 0.94583333 | H13: 0.8897931 | I13: 0.94583333 | J13: 4000 | K13: 32 | L13: 0.9 | M13: (0.01, 0.1, 1.0) | N13: 0.7 | O13: full | P13: grid_selected_by_val_only_no_test | Q13: default | R13: src_v16c_final_6datasets_repeat_rows.csv | S13: 33 | T13: /mnt/data/srcv16c_submission_package/src_v16c_final_6datasets_repeat_rows.csv
... A21: amazon-photo | B21: 9 | C21: 20260428 | E21: class_balanced_random_20_train_30_val_per_class | F21: 1 | G21: 0.89166667 | H21: 0.88331034 | I21: 0.89166667 | J21: 5000 | K21: 32 | L21: 0.9 | M21: (0.01, 0.1, 1.0) | N21: 0.4 | O21: full | P21: grid_selected_by_val_only_no_test | Q21: default | R21: src_v16c_final_6datasets_repeat_rows.csv | S21: 41 | T21: /mnt/data/srcv16c_submission_package/src_v16c_final_6datasets_repeat_rows.csv
A22: chameleon | B22: 0 | C22: 0 | E22: fixed_geom_gcn_split_id_0 | F22: 0.98992674 | G22: 0.739369 | H22: 0.72587719 | I22: 0.73882027 | J22: 8000 | K22: 96 | L22: 0.95 | M22: (0.01, 0.1, 1.0) | N22: 0.6 | O22: full | P22: grid_selected_by_val_only_no_test | R22: src_v16c_main_table_10repeat_rows(1).csv | S22: 2 | T22: /mnt/data/src_v16c_main_table_10repeat_rows(1).csv
A23: chameleon | B23: 1 | C23: 1 | E23: fixed_geom_gcn_split_id_1 | F23: 0.98443223 | G23: 0.70507545 | H23: 0.76315789 | I23: 0.70331668 | J23: 8000 | K23: 64 | L23: 0.9 | M23: (0.01, 0.1, 1.0) | N23: 0.6 | O23: full | P23: grid_selected_by_val_only_no_test | R23: src_v16c_main_table_10repeat_rows(1).csv | S23: 3 | T23: /mnt/data/src_v16c_main_table_10repeat_rows(1).csv
A24: chameleon | B24: 2 | C24: 2 | E24: fixed_geom_gcn_split_id_2 | F24: 0.99175824 | G24: 0.739369 | H24: 0.70394737 | I24: 0.74750391 | J24: 8000 | K24: 96 | L24: 0.99 | M24: (0.01, 0.1, 1.0) | N24: 0.5 | O24: full | P24: grid_selected_by_val_only_no_test | R24: src_v16c_main_table_10repeat_rows(1).csv | S24: 4 | T24: /mnt/data/src_v16c_main_table_10repeat_rows(1).csv
A25: chameleon | B25: 3 | C25: 3 | E25: fixed_geom_gcn_split_id_3 | F25: 0.96336996 | G25: 0.75034294 | H25: 0.71052632 | I25: 0.75113357 | J25: 4000 | K25: 64 | L25: 0.95 | M25: (0.01, 0.1, 1.0) | N25: 0.6 | O25: full | P25: grid_selected_by_val_only_no_test | R25: src_v16c_main_table_10repeat_rows(1).csv | S25: 5 | T25: /mnt/data/src_v16c_main_table_10repeat_rows(1).csv
A26: chameleon | B26: 4 | C26: 4 | E26: fixed_geom_gcn_split_id_4 | F26: 0.98076923 | G26: 0.75171468 | H26: 0.74342105 | I26: 0.75442307 | J26: 6000 | K26: 48 | L26: 0.9 | M26: (0.01, 0.1, 1.0) | N26: 0.5 | O26: full | P26: grid_selected_by_val_only_no_test | R26: src_v16c_main_table_10repeat_rows(1).csv | S26: 6 | T26: /mnt/data/src_v16c_main_table_10repeat_rows(1).csv
A27: chameleon | B27: 5 | C27: 5 | E27: fixed_geom_gcn_split_id_5 | F27: 0.94505495 | G27: 0.73251029 | H27: 0.73464912 | I27: 0.73380421 | J27: 5000 | K27: 64 | L27: 0.9 | M27: (0.01, 0.1, 1.0) | N27: 0.8 | O27: full | P27: grid_selected_by_val_only_no_test | R27: src_v16c_main_table_10repeat_rows(1).csv | S27: 7 | T27: /mnt/data/src_v16c_main_table_10repeat_rows(1).csv
A28: chameleon | B28: 6 | C28: 6 | E28: fixed_geom_gcn_split_id_6 | F28: 0.96062271 | G28: 0.71056241 | H28: 0.70614035 | I28: 0.70920766 | J28: 8000 | K28: 96 | L28: 0.95 | M28: (0.1, 1.0, 10.0) | N28: 0.7 | O28: full | P28: grid_selected_by_val_only_no_test | R28: src_v16c_main_table_10repeat_rows(1).csv | S28: 8 | T28: /mnt/data/src_v16c_main_table_10repeat_rows(1).csv
A29: chameleon | B29: 7 | C29: 7 | E29: fixed_geom_gcn_split_id_7 | F29: 0.99542125 | G29: 0.67901235 | H29: 0.7127193 | I29: 0.67990858 | J29: 8000 | K29: 96 | L29: 0.99 | M29: (0.01, 0.1, 1.0) | N29: 0.6 | O29: full | P29: grid_selected_by_val_only_no_test | R29: src_v16c_main_table_10repeat_rows(1).csv | S29: 9 | T29: /mnt/data/src_v16c_main_table_10repeat_rows(1).csv
A30: chameleon | B30: 8 | C30: 8 | E30: fixed_geom_gcn_split_id_8 | F30: 0.98717949 | G30: 0.73388203 | H30: 0.71929825 | I30: 0.73457794 | J30: 8000 | K30: 64 | L30: 0.9 | M30: (0.01, 0.1, 1.0) | N30: 0.3 | O30: full | P30: grid_selected_by_val_only_no_test | R30: src_v16c_main_table_10repeat_rows(1).csv | S30: 10 | T30: /mnt/data/src_v16c_main_table_10repeat_rows(1).csv
A31: chameleon | B31: 9 | C31: 9 | E31: fixed_geom_gcn_split_id_9 | F31: 0.97710623 | G31: 0.73799726 | H31: 0.72807018 | I31: 0.74009105 | J31: 8000 | K31: 32 | L31: 0.9 | M31: (0.01, 0.1, 1.0) | N31: 0.6 | O31: full | P31: grid_selected_by_val_only_no_test | R31: src_v16c_main_table_10repeat_rows(1).csv | S31: 11 | T31: /mnt/data/src_v16c_main_table_10repeat_rows(1).csv
A32: cornell | B32: 0 | C32: 20260419 | E32: random_stratified_matching_fixed_split0_class_counts | F32: 1 | G32: 0.77966102 | H32: 0.81081081 | I32: 0.58356724 | J32: 4000 | K32: 32 | L32: 0.9 | M32: (0.01, 0.1, 1.0) | N32: 0.2 | O32: full | P32: grid_selected_by_val_only_no_test | Q32: default | R32: src_v16c_final_6datasets_repeat_rows.csv | S32: 12 | T32: /mnt/data/srcv16c_submission_package/src_v16c_final_6datasets_repeat_rows.csv
A33: cornell | B33: 1 | C33: 20260420 | E33: random_stratified_matching_fixed_split0_class_counts | F33: 1 | G33: 0.79661017 | H33: 0.62162162 | I33: 0.69172602 | J33: 4000 | K33: 32 | L33: 0.9 | M33: (0.01, 0.1, 1.0) | N33: 0.2 | O33: full | P33: grid_selected_by_val_only_no_test | Q33: default | R33: src_v16c_final_6datasets_repeat_rows.csv | S33: 13 | T33: /mnt/data/srcv16c_submission_package/src_v16c_final_6datasets_repeat_rows.csv
A34: cornell | B34: 2 | C34: 20260421 | E34: random_stratified_matching_fixed_split0_class_counts | F34: 1 | G34: 0.77966102 | H34: 0.81081081 | I34: 0.58133641 | J34: 4000 | K34: 32 | L34: 0.9 | M34: (0.05, 0.5, 5.0) | N34: 0.2 | O34: full | P34: grid_selected_by_val_only_no_test | Q34: default | R34: src_v16c_final_6datasets_repeat_rows.csv | S34: 14 | T34: /mnt/data/srcv16c_submission_package/src_v16c_final_6datasets_repeat_rows.csv
A35: cornell | B35: 3 | C35: 20260422 | E35: random_stratified_matching_fixed_split0_class_counts | F35: 1 | G35: 0.84745763 | H35: 0.75675676 | I35: 0.61396104 | J35: 4000 | K35: 32 | L35: 0.9 | M35: (0.05, 0.5, 5.0) | N35: 0.2 | O35: full | P35: grid_selected_by_val_only_no_test | Q35: default | R35: src_v16c_final_6datasets_repeat_rows.csv | S35: 15 | T35: /mnt/data/srcv16c_submission_package/src_v16c_final_6datasets_repeat_rows.csv
A36: cornell | B36: 4 | C36: 20260423 | E36: random_stratified_matching_fixed_split0_class_counts | F36: 1 | G36: 0.79661017 | H36: 0.78378378 | I36: 0.57114579 | J36: 4000 | K36: 32 | L36: 0.9 | M36: (0.01, 0.1, 1.0) | N36: 0.2 | O36: full | P36: grid_selected_by_val_only_no_test | Q36: default | R36: src_v16c_final_6datasets_repeat_rows.csv | S36: 16 | T36: /mnt/data/srcv16c_submission_package/src_v16c_final_6datasets_repeat_rows.csv
A37: cornell | B37: 5 | C37: 20260424 | E37: random_stratified_matching_fixed_split0_class_counts | F37: 1 | G37: 0.76271186 | H37: 0.83783784 | I37: 0.52796397 | J37: 4000 | K37: 32 | L37: 0.9 | M37: (0.01, 0.1, 1.0) | N37: 0.2 | O37: full | P37: grid_selected_by_val_only_no_test | Q37: default | R37: src_v16c_final_6datasets_repeat_rows.csv | S37: 17 | T37: /mnt/data/srcv16c_submission_package/src_v16c_final_6datasets_repeat_rows.csv
A38: cornell | B38: 6 | C38: 20260425 | E38: random_stratified_matching_fixed_split0_class_counts | F38: 1 | G38: 0.81355932 | H38: 0.81081081 | I38: 0.66432761 | J38: 6000 | K38: 32 | L38: 0.9 | M38: (0.01, 0.1, 1.0) | N38: 0.2 | O38: full | P38: grid_selected_by_val_only_no_test | Q38: default | R38: src_v16c_final_6datasets_repeat_rows.csv | S38: 18 | T38: /mnt/data/srcv16c_submission_package/src_v16c_final_6datasets_repeat_rows.csv
A39: cornell | B39: 7 | C39: 20260426 | E39: random_stratified_matching_fixed_split0_class_counts | F39: 1 | G39: 0.77966102 | H39: 0.72972973 | I39: 0.56144742 | J39: 5000 | K39: 32 | L39: 0.9 | M39: (0.01, 0.1, 1.0) | N39: 0.2 | O39: full | P39: grid_selected_by_val_only_no_test | Q39: default | R39: src_v16c_final_6datasets_repeat_rows.csv | S39: 19 | T39: /mnt/data/srcv16c_submission_package/src_v16c_final_6datasets_repeat_rows.csv
A40: cornell | B40: 8 | C40: 20260427 | E40: random_stratified_matching_fixed_split0_class_counts | F40: 1 | G40: 0.84745763 | H40: 0.72972973 | I40: 0.70750943 | J40: 4000 | K40: 32 | L40: 0.9 | M40: (0.01, 0.1, 1.0) | N40: 0.7 | O40: full | P40: grid_selected_by_val_only_no_test | Q40: default | R40: src_v16c_final_6datasets_repeat_rows.csv | S40: 20 | T40: /mnt/data/srcv16c_submission_package/src_v16c_final_6datasets_repeat_rows.csv
A41: cornell | B41: 9 | C41: 20260428 | E41: random_stratified_matching_fixed_split0_class_counts | F41: 0.98850575 | G41: 0.84745763 | H41: 0.64864865 | I41: 0.61071429 | J41: 4000 | K41: 32 | L41: 0.9 | M41: (0.1, 1.0, 10.0) | N41: 0.2 | O41: full | P41: grid_selected_by_val_only_no_test | Q41: default | R41: src_v16c_final_6datasets_repeat_rows.csv | S41: 21 | T41: /mnt/data/srcv16c_submission_package/src_v16c_final_6datasets_repeat_rows.csv
A42: texas | B42: 0 | C42: 20260419 | E42: random_stratified_matching_fixed_split0_class_counts | F42: 1 | G42: 0.86206897 | H42: 0.86842105 | I42: 0.75529954 | J42: 4000 | K42: 32 | L42: 0.9 | M42: (0.01, 0.1, 1.0) | N42: 0.2 | O42: full | P42: grid_selected_by_val_only_no_test | Q42: default | R42: src_v16c_final_6datasets_repeat_rows.csv | S42: 2 | T42: /mnt/data/srcv16c_submission_package/src_v16c_final_6datasets_repeat_rows.csv
A43: texas | B43: 1 | C43: 20260420 | E43: random_stratified_matching_fixed_split0_class_counts | F43: 1 | G43: 0.89655172 | H43: 0.89473684 | I43: 0.83717358 | J43: 8000 | K43: 32 | L43: 0.9 | M43: (0.01, 0.1, 1.0) | N43: 0.2 | O43: full | P43: grid_selected_by_val_only_no_test | Q43: default | R43: src_v16c_final_6datasets_repeat_rows.csv | S43: 3 | T43: /mnt/data/srcv16c_submission_package/src_v16c_final_6datasets_repeat_rows.csv
... A61: wisconsin | B61: 9 | C61: 20260428 | E61: random_stratified_matching_fixed_split0_class_counts | F61: 1 | G61: 0.8375 | H61: 0.76470588 | I61: 0.59512195 | J61: 5000 | K61: 32 | L61: 0.9 | M61: (0.05, 0.5, 5.0) | N61: 0.7 | O61: full | P61: grid_selected_by_val_only_no_test | Q61: default | R61: src_v16c_final_6datasets_repeat_rows.csv | S61: 31 | T61: /mnt/data/srcv16c_submission_package/src_v16c_final_6datasets_repeat_rows.csv

Sheet Raw_Strongest_Baseline_Repeats
A1: dataset | B1: method | C1: repeat | D1: split_id | E1: seed | F1: train_acc_raw | G1: val_acc_raw | H1: test_acc_raw | I1: best_epoch | J1: time_sec | K1: params | L1: selection_rule | M1: source_file | N1: source_line | O1: source_path | P1: split_policy
A2: amazon-computers | B2: graphsage | C2: 0 | D2: 0 | E2: 0 | F2: 0.935 | G2: 0.87 | H2: 0.77814668 | I2: 155 | J2: 144.287 | K2: 99530 | L2: baseline_grid_selected_by_val_acc_only_no_test | M2: pyg_baselines_fair_best_by_val_partial(1)(1).csv | N2: 83 | O2: /mnt/data/pyg_baselines_fair_best_by_val_partial(1)(1).csv | P2: class_balanced_random_split_seed
A3: amazon-computers | B3: graphsage | C3: 1 | D3: 0 | E3: 1 | F3: 0.95999998 | G3: 0.86333334 | H3: 0.7959553 | I3: 145 | J3: 154.384 | K3: 99530 | L3: baseline_grid_selected_by_val_acc_only_no_test | M3: pyg_baselines_fair_best_by_val_partial(1)(1).csv | N3: 91 | O3: /mnt/data/pyg_baselines_fair_best_by_val_partial(1)(1).csv | P3: class_balanced_random_split_seed
A4: amazon-computers | B4: graphsage | C4: 2 | D4: 0 | E4: 2 | F4: 0.94499999 | G4: 0.83666664 | H4: 0.76977062 | I4: 90 | J4: 98.91 | K4: 99530 | L4: baseline_grid_selected_by_val_acc_only_no_test | M4: pyg_baselines_fair_best_by_val_partial(1)(1).csv | N4: 99 | O4: /mnt/data/pyg_baselines_fair_best_by_val_partial(1)(1).csv | P4: class_balanced_random_split_seed
A5: amazon-computers | B5: graphsage | C5: 3 | D5: 0 | E5: 3 | F5: 0.95999998 | G5: 0.88 | H5: 0.76886505 | I5: 140 | J5: 130.933 | K5: 99530 | L5: baseline_grid_selected_by_val_acc_only_no_test | M5: pyg_baselines_fair_best_by_val_partial(1)(1).csv | N5: 107 | O5: /mnt/data/pyg_baselines_fair_best_by_val_partial(1)(1).csv | P5: class_balanced_random_split_seed
A6: amazon-computers | B6: graphsage | C6: 4 | D6: 0 | E6: 4 | F6: 0.97000003 | G6: 0.87 | H6: 0.79655904 | I6: 245 | J6: 202.137 | K6: 99530 | L6: baseline_grid_selected_by_val_acc_only_no_test | M6: pyg_baselines_fair_best_by_val_partial(1)(1).csv | N6: 115 | O6: /mnt/data/pyg_baselines_fair_best_by_val_partial(1)(1).csv | P6: class_balanced_random_split_seed
A7: amazon-computers | B7: graphsage | C7: 5 | D7: 0 | E7: 5 | F7: 0.96499997 | G7: 0.87 | H7: 0.7413975 | I7: 195 | J7: 168.665 | K7: 99530 | L7: baseline_grid_selected_by_val_acc_only_no_test | M7: pyg_baselines_fair_best_by_val_partial(1)(1).csv | N7: 123 | O7: /mnt/data/pyg_baselines_fair_best_by_val_partial(1)(1).csv | P7: class_balanced_random_split_seed
A8: amazon-computers | B8: graphsage | C8: 6 | D8: 0 | E8: 6 | F8: 0.97500002 | G8: 0.80000001 | H8: 0.75882888 | I8: 70 | J8: 83.061 | K8: 99530 | L8: baseline_grid_selected_by_val_acc_only_no_test | M8: pyg_baselines_fair_best_by_val_partial(1)(1).csv | N8: 131 | O8: /mnt/data/pyg_baselines_fair_best_by_val_partial(1)(1).csv | P8: class_balanced_random_split_seed
A9: amazon-computers | B9: graphsage | C9: 7 | D9: 0 | E9: 7 | F9: 0.96499997 | G9: 0.87 | H9: 0.79618168 | I9: 200 | J9: 171.885 | K9: 99530 | L9: baseline_grid_selected_by_val_acc_only_no_test | M9: pyg_baselines_fair_best_by_val_partial(1)(1).csv | N9: 139 | O9: /mnt/data/pyg_baselines_fair_best_by_val_partial(1)(1).csv | P9: class_balanced_random_split_seed
A10: amazon-computers | B10: graphsage | C10: 8 | D10: 0 | E10: 8 | F10: 0.95999998 | G10: 0.8433333 | H10: 0.75784785 | I10: 175 | J10: 155.098 | K10: 99530 | L10: baseline_grid_selected_by_val_acc_only_no_test | M10: pyg_baselines_fair_best_by_val_partial(1)(1).csv | N10: 147 | O10: /mnt/data/pyg_baselines_fair_best_by_val_partial(1)(1).csv | P10: class_balanced_random_split_seed
A11: amazon-computers | B11: graphsage | C11: 9 | D11: 0 | E11: 9 | F11: 0.94999999 | G11: 0.84666669 | H11: 0.78229702 | I11: 125 | J11: 120.44 | K11: 99530 | L11: baseline_grid_selected_by_val_acc_only_no_test | M11: pyg_baselines_fair_best_by_val_partial(1)(1).csv | N11: 155 | O11: /mnt/data/pyg_baselines_fair_best_by_val_partial(1)(1).csv | P11: class_balanced_random_split_seed
A12: amazon-photo | B12: graphsage | C12: 0 | D12: 0 | E12: 0 | F12: 0.98750001 | G12: 0.92083335 | H12: 0.85806894 | I12: 185 | J12: 80.442 | K12: 96456 | L12: baseline_grid_selected_by_val_acc_only_no_test | M12: pyg_baselines_fair_best_by_val_partial(1)(1).csv | N12: 3 | O12: /mnt/data/pyg_baselines_fair_best_by_val_partial(1)(1).csv | P12: class_balanced_random_split_seed
A13: amazon-photo | B13: graphsage | C13: 1 | D13: 0 | E13: 1 | F13: 0.98750001 | G13: 0.91250002 | H13: 0.8710345 | I13: 125 | J13: 56.961 | K13: 96456 | L13: baseline_grid_selected_by_val_acc_only_no_test | M13: pyg_baselines_fair_best_by_val_partial(1)(1).csv | N13: 11 | O13: /mnt/data/pyg_baselines_fair_best_by_val_partial(1)(1).csv | P13: class_balanced_random_split_seed
... A61: wisconsin | B61: graphsage | C61: 9 | D61: 9 | E61: 9 | F61: 1 | G61: 0.8125 | H61: 0.80392158 | I61: 205 | J61: 1.707 | K61: 218693 | L61: baseline_grid_selected_by_val_acc_only_no_test | M61: pyg_baselines_fair_best_by_val_partial(1)(1).csv | N61: 635 | O61: /mnt/data/pyg_baselines_fair_best_by_val_partial(1)(1).csv | P61: geom_gcn_mask_split_id

Sheet Baseline_Method_Stats
A1: dataset | B1: method | C1: n | D1: train_mean_% | E1: train_std_% | F1: val_mean_% | G1: val_std_% | H1: test_mean_% | I1: test_std_% | J1: is_strongest_by_test_mean
A2: amazon-computers | B2: GraphSAGE | C2: 10 | D2: 95.849999 | E2: 1.2030059 | F2: 85.5 | G2: 2.3946959 | H2: 77.458496 | I2: 1.8749279 | J2: YES
A3: amazon-computers | B3: Correct&Smooth | C3: 10 | D3: 99.85 | E3: 0.24152272 | F3: 84.733334 | G3: 1.8711595 | H3: 76.353759 | I3: 2.1734331
A4: amazon-computers | B4: SIGN | C4: 10 | D4: 97.500001 | E4: 1.2472201 | F4: 83.666667 | G4: 2.5819888 | H4: 74.812104 | I4: 1.7871347
A5: amazon-computers | B5: GAT | C5: 10 | D5: 77.75 | E5: 8.882723 | F5: 74.766666 | G5: 5.1353298 | H5: 69.729852 | I5: 5.1225312
A6: amazon-computers | B6: APPNP | C6: 10 | D6: 73.7 | E6: 4.5411697 | F6: 71.500001 | G6: 3.9542132 | H6: 67.561878 | I6: 3.9354599
A7: amazon-computers | B7: MLP+Prop | C7: 10 | D7: 74.350001 | E7: 5.2283942 | F7: 71.899999 | G7: 3.6752437 | H7: 67.396621 | I7: 3.9524559
A8: amazon-computers | B8: LINKX | C8: 10 | D8: 99.95 | E8: 0.15811373 | F8: 66.266667 | G8: 2.9008299 | H8: 48.942801 | I8: 7.1399633
A9: amazon-computers | B9: GCNII | C9: 10 | D9: 32.55 | E9: 12.84188 | F9: 33.233333 | G9: 11.832211 | H9: 27.303049 | I9: 14.797903
A10: amazon-photo | B10: GraphSAGE | C10: 10 | D10: 98.750001 | E10: 0.88388263 | F10: 91 | G10: 1.2453632 | H10: 87.586208 | I10: 1.3272796 | J10: YES
A11: amazon-photo | B11: Correct&Smooth | C11: 10 | D11: 99.9375 | E11: 0.19764311 | F11: 89.999999 | G11: 1.4958797 | H11: 86.244138 | I11: 2.355442
A12: amazon-photo | B12: GAT | C12: 10 | D12: 90.437499 | E12: 4.0509978 | F12: 86.666667 | G12: 2.1063523 | H12: 84.633103 | I12: 2.6291649
A13: amazon-photo | B13: SIGN | C13: 10 | D13: 98.375 | E13: 1.3881942 | F13: 88.416666 | G13: 2.34718 | H13: 84.235862 | I13: 2.076039
A14: amazon-photo | B14: MLP+Prop | C14: 10 | D14: 87.6875 | E14: 3.7965845 | F14: 84.624999 | G14: 3.7291076 | H14: 83.586208 | I14: 2.8982161
A15: amazon-photo | B15: APPNP | C15: 10 | D15: 87.25 | E15: 3.0788263 | F15: 83.708335 | G15: 4.0035188 | H15: 83.006896 | I15: 2.1305167
A16: amazon-photo | B16: LINKX | C16: 10 | D16: 100 | E16: 0 | F16: 73.5 | G16: 3.9878295 | H16: 64.209655 | I16: 3.1594379
A17: amazon-photo | B17: GCNII | C17: 10 | D17: 64.9375 | E17: 14.914251 | F17: 61.291667 | G17: 13.734489 | H17: 57.477241 | I17: 15.207321
A18: chameleon | B18: LINKX | C18: 10 | D18: 99.890109 | E18: 0.19688015 | F18: 72.551439 | G18: 1.5898134 | H18: 71.249999 | I18: 1.485375 | J18: YES
A19: chameleon | B19: GraphSAGE | C19: 10 | D19: 98.424908 | E19: 0.80043154 | F19: 60.397805 | G19: 1.9335119 | H19: 60.285088 | I19: 0.90978707
A20: chameleon | B20: GAT | C20: 10 | D20: 67.747251 | E20: 1.9819177 | F20: 58.984911 | G20: 1.0121596 | H20: 58.464911 | I20: 1.1705048
A21: chameleon | B21: SIGN | C21: 10 | D21: 99.065933 | E21: 0.41585862 | F21: 56.941016 | G21: 2.2829886 | H21: 56.864035 | I21: 1.7817366
A22: chameleon | B22: Correct&Smooth | C22: 10 | D22: 96.785713 | E22: 0.56028176 | F22: 48.943759 | G22: 1.4164337 | H22: 48.179824 | I22: 3.5767207
A23: chameleon | B23: MLP+Prop | C23: 10 | D23: 66.456044 | E23: 3.8257614 | F23: 46.85871 | G23: 1.2707859 | H23: 46.184211 | I23: 1.9318168
A24: chameleon | B24: APPNP | C24: 10 | D24: 61.575091 | E24: 2.7357653 | F24: 46.021948 | G24: 1.2375277 | H24: 45.548246 | I24: 2.4355386
A25: chameleon | B25: GCNII | C25: 10 | D25: 45.576923 | E25: 2.7055754 | F25: 41.440329 | G25: 1.5335858 | H25: 40.745614 | I25: 2.3088306
A26: cornell | B26: GraphSAGE | C26: 10 | D26: 98.735632 | E26: 1.9118729 | F26: 74.745763 | G26: 6.561947 | H26: 70.27027 | I26: 5.6977983 | J26: YES
A27: cornell | B27: SIGN | C27: 10 | D27: 97.241379 | E27: 2.7200361 | F27: 72.033899 | G27: 6.045461 | H27: 67.837837 | I27: 4.4954863
A28: cornell | B28: LINKX | C28: 10 | D28: 98.62069 | E28: 3.331351 | F28: 64.576272 | G28: 6.1084911 | H28: 62.432432 | I28: 6.2998676
A29: cornell | B29: Correct&Smooth | C29: 10 | D29: 96.781609 | E29: 1.9385601 | F29: 60.847458 | G29: 8.2821859 | H29: 55.945945 | I29: 12.157156
A30: cornell | B30: GAT | C30: 10 | D30: 55.747125 | E30: 6.3247418 | F30: 51.016949 | G30: 9.2299853 | H30: 44.324324 | I30: 6.5214268
A31: cornell | B31: APPNP | C31: 10 | D31: 44.137931 | E31: 4.1336714 | F31: 47.118644 | G31: 6.8172223 | H31: 42.702703 | I31: 5.8106355
A32: cornell | B32: GCNII | C32: 10 | D32: 44.137931 | E32: 4.1336714 | F32: 47.118644 | G32: 6.8172223 | H32: 42.702703 | I32: 5.8106355
A33: cornell | B33: MLP+Prop | C33: 10 | D33: 44.712644 | E33: 4.2819409 | F33: 47.118644 | G33: 6.8172223 | H33: 42.702703 | I33: 5.8106355
A34: texas | B34: GraphSAGE | C34: 10 | D34: 97.011493 | E34: 3.3489302 | F34: 82.20339 | G34: 6.1501521 | H34: 78.378378 | I34: 7.9565402 | J34: YES
A35: texas | B35: SIGN | C35: 10 | D35: 98.850573 | E35: 1.0836889 | F35: 78.644068 | G35: 5.717111 | H35: 72.432432 | I35: 6.7176038
A36: texas | B36: LINKX | C36: 10 | D36: 93.333333 | E36: 10.834176 | F36: 65.423729 | G36: 5.2515031 | H36: 59.459459 | I36: 8.3546112
A37: texas | B37: Correct&Smooth | C37: 10 | D37: 96.206896 | E37: 2.0310118 | F37: 61.864407 | G37: 10.904102 | H37: 59.189188 | I37: 6.4274081
A38: texas | B38: APPNP | C38: 10 | D38: 53.448275 | E38: 3.840985 | F38: 55.423729 | G38: 5.6525424 | H38: 58.918919 | I38: 4.5582368
A39: texas | B39: GCNII | C39: 10 | D39: 53.448275 | E39: 3.840985 | F39: 55.423729 | G39: 5.6525424 | H39: 58.918919 | I39: 4.5582368
A40: texas | B40: MLP+Prop | C40: 10 | D40: 53.448275 | E40: 3.840985 | F40: 55.423729 | G40: 5.6525424 | H40: 58.918919 | I40: 4.5582368
...

Sheet Compact_Summary
A1: dataset | B1: strongest_baseline_method | C1: baseline_n | D1: baseline_val_mean_% | E1: baseline_val_std_% | F1: baseline_test_mean_% | G1: baseline_test_std_% | H1: src_v16c_n | I1: src_val_mean_% | J1: src_val_std_% | K1: src_test_mean_% | L1: src_test_std_% | M1: gain_vs_baseline_pp
A2: amazon-computers | B2: GraphSAGE | C2: =COUNT(Raw_Strongest_Baseline_Repeats!H2:H11) -> 10 | D2: =AVERAGE(Raw_Strongest_Baseline_Repeats!G2:G11)*100 -> 85.5 | E2: =_xlfn.STDEV.S(Raw_Strongest_Baseline_Repeats!G2:G11)*100 -> 2.3946959 | F2: =AVERAGE(Raw_Strongest_Baseline_Repeats!H2:H11)*100 -> 77.458496 | G2: =_xlfn.STDEV.S(Raw_Strongest_Baseline_Repeats!H2:H11)*100 -> 1.8749279 | H2: =COUNT(Raw_SRC_V16C_Repeats!H2:H11) -> 10 | I2: =AVERAGE(Raw_SRC_V16C_Repeats!G2:G11)*100 -> 85.466667 | J2: =_xlfn.STDEV.S(Raw_SRC_V16C_Repeats!G2:G11)*100 -> 1.239275 | K2: =AVERAGE(Raw_SRC_V16C_Repeats!H2:H11)*100 -> 78.709629 | L2: =_xlfn.STDEV.S(Raw_SRC_V16C_Repeats!H2:H11)*100 -> 1.1547438 | M2: =K2-F2 -> 1.2511326
A3: amazon-photo | B3: GraphSAGE | C3: =COUNT(Raw_Strongest_Baseline_Repeats!H12:H21) -> 10 | D3: =AVERAGE(Raw_Strongest_Baseline_Repeats!G12:G21)*100 -> 91 | E3: =_xlfn.STDEV.S(Raw_Strongest_Baseline_Repeats!G12:G21)*100 -> 1.2453632 | F3: =AVERAGE(Raw_Strongest_Baseline_Repeats!H12:H21)*100 -> 87.586208 | G3: =_xlfn.STDEV.S(Raw_Strongest_Baseline_Repeats!H12:H21)*100 -> 1.3272796 | H3: =COUNT(Raw_SRC_V16C_Repeats!H12:H21) -> 10 | I3: =AVERAGE(Raw_SRC_V16C_Repeats!G12:G21)*100 -> 91.666667 | J3: =_xlfn.STDEV.S(Raw_SRC_V16C_Repeats!G12:G21)*100 -> 2.2047928 | K3: =AVERAGE(Raw_SRC_V16C_Repeats!H12:H21)*100 -> 88.76 | L3: =_xlfn.STDEV.S(Raw_SRC_V16C_Repeats!H12:H21)*100 -> 1.3532785 | M3: =K3-F3 -> 1.173792
A4: chameleon | B4: LINKX | C4: =COUNT(Raw_Strongest_Baseline_Repeats!H22:H31) -> 10 | D4: =AVERAGE(Raw_Strongest_Baseline_Repeats!G22:G31)*100 -> 72.551439 | E4: =_xlfn.STDEV.S(Raw_Strongest_Baseline_Repeats!G22:G31)*100 -> 1.5898134 | F4: =AVERAGE(Raw_Strongest_Baseline_Repeats!H22:H31)*100 -> 71.249999 | G4: =_xlfn.STDEV.S(Raw_Strongest_Baseline_Repeats!H22:H31)*100 -> 1.485375 | H4: =COUNT(Raw_SRC_V16C_Repeats!H22:H31) -> 10 | I4: =AVERAGE(Raw_SRC_V16C_Repeats!G22:G31)*100 -> 72.798354 | J4: =_xlfn.STDEV.S(Raw_SRC_V16C_Repeats!G22:G31)*100 -> 2.2862826 | K4: =AVERAGE(Raw_SRC_V16C_Repeats!H22:H31)*100 -> 72.47807 | L4: =_xlfn.STDEV.S(Raw_SRC_V16C_Repeats!H22:H31)*100 -> 1.8528935 | M4: =K4-F4 -> 1.2280708
A5: cornell | B5: GraphSAGE | C5: =COUNT(Raw_Strongest_Baseline_Repeats!H32:H41) -> 10 | D5: =AVERAGE(Raw_Strongest_Baseline_Repeats!G32:G41)*100 -> 74.745763 | E5: =_xlfn.STDEV.S(Raw_Strongest_Baseline_Repeats!G32:G41)*100 -> 6.561947 | F5: =AVERAGE(Raw_Strongest_Baseline_Repeats!H32:H41)*100 -> 70.27027 | G5: =_xlfn.STDEV.S(Raw_Strongest_Baseline_Repeats!H32:H41)*100 -> 5.6977983 | H5: =COUNT(Raw_SRC_V16C_Repeats!H32:H41) -> 10 | I5: =AVERAGE(Raw_SRC_V16C_Repeats!G32:G41)*100 -> 80.508475 | J5: =_xlfn.STDEV.S(Raw_SRC_V16C_Repeats!G32:G41)*100 -> 3.2208345 | K5: =AVERAGE(Raw_SRC_V16C_Repeats!H32:H41)*100 -> 75.405405 | L5: =_xlfn.STDEV.S(Raw_SRC_V16C_Repeats!H32:H41)*100 -> 7.257706 | M5: =K5-F5 -> 5.1351359
A6: texas | B6: GraphSAGE | C6: =COUNT(Raw_Strongest_Baseline_Repeats!H42:H51) -> 10 | D6: =AVERAGE(Raw_Strongest_Baseline_Repeats!G42:G51)*100 -> 82.20339 | E6: =_xlfn.STDEV.S(Raw_Strongest_Baseline_Repeats!G42:G51)*100 -> 6.1501521 | F6: =AVERAGE(Raw_Strongest_Baseline_Repeats!H42:H51)*100 -> 78.378378 | G6: =_xlfn.STDEV.S(Raw_Strongest_Baseline_Repeats!H42:H51)*100 -> 7.9565402 | H6: =COUNT(Raw_SRC_V16C_Repeats!H42:H51) -> 10 | I6: =AVERAGE(Raw_SRC_V16C_Repeats!G42:G51)*100 -> 87.758621 | J6: =_xlfn.STDEV.S(Raw_SRC_V16C_Repeats!G42:G51)*100 -> 2.4985132 | K6: =AVERAGE(Raw_SRC_V16C_Repeats!H42:H51)*100 -> 86.315789 | L6: =_xlfn.STDEV.S(Raw_SRC_V16C_Repeats!H42:H51)*100 -> 4.0768246 | M6: =K6-F6 -> 7.9374113
A7: wisconsin | B7: GraphSAGE | C7: =COUNT(Raw_Strongest_Baseline_Repeats!H52:H61) -> 10 | D7: =AVERAGE(Raw_Strongest_Baseline_Repeats!G52:G61)*100 -> 82.125 | E7: =_xlfn.STDEV.S(Raw_Strongest_Baseline_Repeats!G52:G61)*100 -> 4.1268926 | F7: =AVERAGE(Raw_Strongest_Baseline_Repeats!H52:H61)*100 -> 81.960785 | G7: =_xlfn.STDEV.S(Raw_Strongest_Baseline_Repeats!H52:H61)*100 -> 3.1751522 | H7: =COUNT(Raw_SRC_V16C_Repeats!H52:H61) -> 10 | I7: =AVERAGE(Raw_SRC_V16C_Repeats!G52:G61)*100 -> 85.25 | J7: =_xlfn.STDEV.S(Raw_SRC_V16C_Repeats!G52:G61)*100 -> 1.5365907 | K7: =AVERAGE(Raw_SRC_V16C_Repeats!H52:H61)*100 -> 84.313725 | L7: =_xlfn.STDEV.S(Raw_SRC_V16C_Repeats!H52:H61)*100 -> 4.2357782 | M7: =K7-F7 -> 2.3529401
A9: Average | F9: =AVERAGE(F2:F7) -> 77.817356 | K9: =AVERAGE(K2:K7) -> 80.997103 | M9: =AVERAGE(M2:M7) -> 3.1797471

Sheet Final_Table_Sections
A1: Dataset | B1: Entry | C1: Method | D1: n | E1: Train Mean % | F1: Train Std % | G1: Val Mean % | H1: Val Std % | I1: Test Mean % | J1: Test Std % | K1: Gain vs strongest baseline (pp) | L1: Repeat | M1: Seed | N1: Split ID | O1: Split policy | P1: Train Acc % | Q1: Val Acc % | R1: Test Acc % | S1: Test Acc raw | T1: Val Bal Acc % | U1: top_k | V1: dim | W1: energy | X1: alphas | Y1: w | Z1: feature_variant | AA1: selection_rule | AB1: source_file | AC1: source_line
A2: Dataset: amazon-computers
A3: amazon-computers | B3: Strongest baseline summary | C3: GraphSAGE | D3: =COUNT(Raw_Strongest_Baseline_Repeats!H2:H11) -> 10 | E3: =AVERAGE(Raw_Strongest_Baseline_Repeats!F2:F11)*100 -> 95.849999 | F3: =_xlfn.STDEV.S(Raw_Strongest_Baseline_Repeats!F2:F11)*100 -> 1.2030059 | G3: =AVERAGE(Raw_Strongest_Baseline_Repeats!G2:G11)*100 -> 85.5 | H3: =_xlfn.STDEV.S(Raw_Strongest_Baseline_Repeats!G2:G11)*100 -> 2.3946959 | I3: =AVERAGE(Raw_Strongest_Baseline_Repeats!H2:H11)*100 -> 77.458496 | J3: =_xlfn.STDEV.S(Raw_Strongest_Baseline_Repeats!H2:H11)*100 -> 1.8749279 | AB3: pyg_baselines_fair_best_by_val_partial(1)(1).csv | AC3: rows 2-11 in Raw_Strongest_Baseline_Repeats
A4: amazon-computers | B4: SRC-v16c summary | C4: SRC-v16c | D4: =COUNT(Raw_SRC_V16C_Repeats!H2:H11) -> 10 | E4: =AVERAGE(Raw_SRC_V16C_Repeats!F2:F11)*100 -> 100 | F4: =_xlfn.STDEV.S(Raw_SRC_V16C_Repeats!F2:F11)*100 -> 0 | G4: =AVERAGE(Raw_SRC_V16C_Repeats!G2:G11)*100 -> 85.466667 | H4: =_xlfn.STDEV.S(Raw_SRC_V16C_Repeats!G2:G11)*100 -> 1.239275 | I4: =AVERAGE(Raw_SRC_V16C_Repeats!H2:H11)*100 -> 78.709629 | J4: =_xlfn.STDEV.S(Raw_SRC_V16C_Repeats!H2:H11)*100 -> 1.1547438 | K4: =I4-I3 -> 1.2511326 | AB4: SRC-v16c repeat rows: final 6-dataset package + chameleon CSV | AC4: Raw_SRC_V16C_Repeats rows 2-11
A5: =Raw_SRC_V16C_Repeats!A2 -> amazon-computers | B5: ="SRC-v16c repeat "&Raw_SRC_V16C_Repeats!B2 -> SRC-v16c repeat 0 | C5: SRC-v16c | L5: =Raw_SRC_V16C_Repeats!B2 -> 0 | M5: =Raw_SRC_V16C_Repeats!C2 -> 20260419 | N5: =Raw_SRC_V16C_Repeats!D2 -> 0 | O5: =Raw_SRC_V16C_Repeats!E2 -> class_balanced_random_20_train_30_val_per_class | P5: =Raw_SRC_V16C_Repeats!F2*100 -> 100 | Q5: =Raw_SRC_V16C_Repeats!G2*100 -> 85.333333 | R5: =Raw_SRC_V16C_Repeats!H2*100 -> 77.618473 | S5: =Raw_SRC_V16C_Repeats!H2 -> 0.77618473 | T5: =Raw_SRC_V16C_Repeats!I2*100 -> 85.333333 | U5: =Raw_SRC_V16C_Repeats!J2 -> 4000 | V5: =Raw_SRC_V16C_Repeats!K2 -> 64 | W5: =Raw_SRC_V16C_Repeats!L2 -> 0.95 | X5: =Raw_SRC_V16C_Repeats!M2 -> (0.05, 0.5, 5.0) | Y5: =Raw_SRC_V16C_Repeats!N2 -> 0.6 | Z5: =Raw_SRC_V16C_Repeats!O2 -> full | AA5: =Raw_SRC_V16C_Repeats!P2 -> grid_selected_by_val_only_no_test | AB5: =Raw_SRC_V16C_Repeats!R2 -> src_v16c_final_6datasets_repeat_rows.csv | AC5: =Raw_SRC_V16C_Repeats!S2 -> 42
A6: =Raw_SRC_V16C_Repeats!A3 -> amazon-computers | B6: ="SRC-v16c repeat "&Raw_SRC_V16C_Repeats!B3 -> SRC-v16c repeat 1 | C6: SRC-v16c | L6: =Raw_SRC_V16C_Repeats!B3 -> 1 | M6: =Raw_SRC_V16C_Repeats!C3 -> 20260420 | N6: =Raw_SRC_V16C_Repeats!D3 -> 0 | O6: =Raw_SRC_V16C_Repeats!E3 -> class_balanced_random_20_train_30_val_per_class | P6: =Raw_SRC_V16C_Repeats!F3*100 -> 100 | Q6: =Raw_SRC_V16C_Repeats!G3*100 -> 86.666667 | R6: =Raw_SRC_V16C_Repeats!H3*100 -> 80.485964 | S6: =Raw_SRC_V16C_Repeats!H3 -> 0.80485964 | T6: =Raw_SRC_V16C_Repeats!I3*100 -> 86.666667 | U6: =Raw_SRC_V16C_Repeats!J3 -> 4000 | V6: =Raw_SRC_V16C_Repeats!K3 -> 64 | W6: =Raw_SRC_V16C_Repeats!L3 -> 0.95 | X6: =Raw_SRC_V16C_Repeats!M3 -> (0.01, 0.1, 1.0) | Y6: =Raw_SRC_V16C_Repeats!N3 -> 0.4 | Z6: =Raw_SRC_V16C_Repeats!O3 -> full | AA6: =Raw_SRC_V16C_Repeats!P3 -> grid_selected_by_val_only_no_test | AB6: =Raw_SRC_V16C_Repeats!R3 -> src_v16c_final_6datasets_repeat_rows.csv | AC6: =Raw_SRC_V16C_Repeats!S3 -> 43
A7: =Raw_SRC_V16C_Repeats!A4 -> amazon-computers | B7: ="SRC-v16c repeat "&Raw_SRC_V16C_Repeats!B4 -> SRC-v16c repeat 2 | C7: SRC-v16c | L7: =Raw_SRC_V16C_Repeats!B4 -> 2 | M7: =Raw_SRC_V16C_Repeats!C4 -> 20260421 | N7: =Raw_SRC_V16C_Repeats!D4 -> 0 | O7: =Raw_SRC_V16C_Repeats!E4 -> class_balanced_random_20_train_30_val_per_class | P7: =Raw_SRC_V16C_Repeats!F4*100 -> 100 | Q7: =Raw_SRC_V16C_Repeats!G4*100 -> 84.333333 | R7: =Raw_SRC_V16C_Repeats!H4*100 -> 77.41473 | S7: =Raw_SRC_V16C_Repeats!H4 -> 0.7741473 | T7: =Raw_SRC_V16C_Repeats!I4*100 -> 84.333333 | U7: =Raw_SRC_V16C_Repeats!J4 -> 4000 | V7: =Raw_SRC_V16C_Repeats!K4 -> 64 | W7: =Raw_SRC_V16C_Repeats!L4 -> 0.99 | X7: =Raw_SRC_V16C_Repeats!M4 -> (0.05, 0.5, 5.0) | Y7: =Raw_SRC_V16C_Repeats!N4 -> 0.6 | Z7: =Raw_SRC_V16C_Repeats!O4 -> full | AA7: =Raw_SRC_V16C_Repeats!P4 -> grid_selected_by_val_only_no_test | AB7: =Raw_SRC_V16C_Repeats!R4 -> src_v16c_final_6datasets_repeat_rows.csv | AC7: =Raw_SRC_V16C_Repeats!S4 -> 44
A8: =Raw_SRC_V16C_Repeats!A5 -> amazon-computers | B8: ="SRC-v16c repeat "&Raw_SRC_V16C_Repeats!B5 -> SRC-v16c repeat 3 | C8: SRC-v16c | L8: =Raw_SRC_V16C_Repeats!B5 -> 3 | M8: =Raw_SRC_V16C_Repeats!C5 -> 20260422 | N8: =Raw_SRC_V16C_Repeats!D5 -> 0 | O8: =Raw_SRC_V16C_Repeats!E5 -> class_balanced_random_20_train_30_val_per_class | P8: =Raw_SRC_V16C_Repeats!F5*100 -> 100 | Q8: =Raw_SRC_V16C_Repeats!G5*100 -> 86 | R8: =Raw_SRC_V16C_Repeats!H5*100 -> 79.603079 | S8: =Raw_SRC_V16C_Repeats!H5 -> 0.79603079 | T8: =Raw_SRC_V16C_Repeats!I5*100 -> 86 | U8: =Raw_SRC_V16C_Repeats!J5 -> 4000 | V8: =Raw_SRC_V16C_Repeats!K5 -> 64 | W8: =Raw_SRC_V16C_Repeats!L5 -> 0.95 | X8: =Raw_SRC_V16C_Repeats!M5 -> (0.01, 0.1, 1.0) | Y8: =Raw_SRC_V16C_Repeats!N5 -> 0.6 | Z8: =Raw_SRC_V16C_Repeats!O5 -> full | AA8: =Raw_SRC_V16C_Repeats!P5 -> grid_selected_by_val_only_no_test | AB8: =Raw_SRC_V16C_Repeats!R5 -> src_v16c_final_6datasets_repeat_rows.csv | AC8: =Raw_SRC_V16C_Repeats!S5 -> 45
A9: =Raw_SRC_V16C_Repeats!A6 -> amazon-computers | B9: ="SRC-v16c repeat "&Raw_SRC_V16C_Repeats!B6 -> SRC-v16c repeat 4 | C9: SRC-v16c | L9: =Raw_SRC_V16C_Repeats!B6 -> 4 | M9: =Raw_SRC_V16C_Repeats!C6 -> 20260423 | N9: =Raw_SRC_V16C_Repeats!D6 -> 0 | O9: =Raw_SRC_V16C_Repeats!E6 -> class_balanced_random_20_train_30_val_per_class | P9: =Raw_SRC_V16C_Repeats!F6*100 -> 100 | Q9: =Raw_SRC_V16C_Repeats!G6*100 -> 86 | R9: =Raw_SRC_V16C_Repeats!H6*100 -> 79.022034 | S9: =Raw_SRC_V16C_Repeats!H6 -> 0.79022034 | T9: =Raw_SRC_V16C_Repeats!I6*100 -> 86 | U9: =Raw_SRC_V16C_Repeats!J6 -> 4000 | V9: =Raw_SRC_V16C_Repeats!K6 -> 64 | W9: =Raw_SRC_V16C_Repeats!L6 -> 0.95 | X9: =Raw_SRC_V16C_Repeats!M6 -> (0.01, 0.1, 1.0) | Y9: =Raw_SRC_V16C_Repeats!N6 -> 0.4 | Z9: =Raw_SRC_V16C_Repeats!O6 -> full | AA9: =Raw_SRC_V16C_Repeats!P6 -> grid_selected_by_val_only_no_test | AB9: =Raw_SRC_V16C_Repeats!R6 -> src_v16c_final_6datasets_repeat_rows.csv | AC9: =Raw_SRC_V16C_Repeats!S6 -> 46
A10: =Raw_SRC_V16C_Repeats!A7 -> amazon-computers | B10: ="SRC-v16c repeat "&Raw_SRC_V16C_Repeats!B7 -> SRC-v16c repeat 5 | C10: SRC-v16c | L10: =Raw_SRC_V16C_Repeats!B7 -> 5 | M10: =Raw_SRC_V16C_Repeats!C7 -> 20260424 | N10: =Raw_SRC_V16C_Repeats!D7 -> 0 | O10: =Raw_SRC_V16C_Repeats!E7 -> class_balanced_random_20_train_30_val_per_class | P10: =Raw_SRC_V16C_Repeats!F7*100 -> 100 | Q10: =Raw_SRC_V16C_Repeats!G7*100 -> 84.666667 | R10: =Raw_SRC_V16C_Repeats!H7*100 -> 79.014488 | S10: =Raw_SRC_V16C_Repeats!H7 -> 0.79014488 | T10: =Raw_SRC_V16C_Repeats!I7*100 -> 84.666667 | U10: =Raw_SRC_V16C_Repeats!J7 -> 4000 | V10: =Raw_SRC_V16C_Repeats!K7 -> 64 | W10: =Raw_SRC_V16C_Repeats!L7 -> 0.95 | X10: =Raw_SRC_V16C_Repeats!M7 -> (0.01, 0.1, 1.0) | Y10: =Raw_SRC_V16C_Repeats!N7 -> 0.4 | Z10: =Raw_SRC_V16C_Repeats!O7 -> full | AA10: =Raw_SRC_V16C_Repeats!P7 -> grid_selected_by_val_only_no_test | AB10: =Raw_SRC_V16C_Repeats!R7 -> src_v16c_final_6datasets_repeat_rows.csv | AC10: =Raw_SRC_V16C_Repeats!S7 -> 47
A11: =Raw_SRC_V16C_Repeats!A8 -> amazon-computers | B11: ="SRC-v16c repeat "&Raw_SRC_V16C_Repeats!B8 -> SRC-v16c repeat 6 | C11: SRC-v16c | L11: =Raw_SRC_V16C_Repeats!B8 -> 6 | M11: =Raw_SRC_V16C_Repeats!C8 -> 20260425 | N11: =Raw_SRC_V16C_Repeats!D8 -> 0 | O11: =Raw_SRC_V16C_Repeats!E8 -> class_balanced_random_20_train_30_val_per_class | P11: =Raw_SRC_V16C_Repeats!F8*100 -> 100 | Q11: =Raw_SRC_V16C_Repeats!G8*100 -> 86 | R11: =Raw_SRC_V16C_Repeats!H8*100 -> 78.773015 | S11: =Raw_SRC_V16C_Repeats!H8 -> 0.78773015 | T11: =Raw_SRC_V16C_Repeats!I8*100 -> 86 | U11: =Raw_SRC_V16C_Repeats!J8 -> 4000 | V11: =Raw_SRC_V16C_Repeats!K8 -> 64 | W11: =Raw_SRC_V16C_Repeats!L8 -> 0.95 | X11: =Raw_SRC_V16C_Repeats!M8 -> (0.01, 0.1, 1.0) | Y11: =Raw_SRC_V16C_Repeats!N8 -> 0.4 | Z11: =Raw_SRC_V16C_Repeats!O8 -> full | AA11: =Raw_SRC_V16C_Repeats!P8 -> grid_selected_by_val_only_no_test | AB11: =Raw_SRC_V16C_Repeats!R8 -> src_v16c_final_6datasets_repeat_rows.csv | AC11: =Raw_SRC_V16C_Repeats!S8 -> 48
A12: =Raw_SRC_V16C_Repeats!A9 -> amazon-computers | B12: ="SRC-v16c repeat "&Raw_SRC_V16C_Repeats!B9 -> SRC-v16c repeat 7 | C12: SRC-v16c | L12: =Raw_SRC_V16C_Repeats!B9 -> 7 | M12: =Raw_SRC_V16C_Repeats!C9 -> 20260426 | N12: =Raw_SRC_V16C_Repeats!D9 -> 0 | O12: =Raw_SRC_V16C_Repeats!E9 -> class_balanced_random_20_train_30_val_per_class | P12: =Raw_SRC_V16C_Repeats!F9*100 -> 100 | Q12: =Raw_SRC_V16C_Repeats!G9*100 -> 85.333333 | R12: =Raw_SRC_V16C_Repeats!H9*100 -> 80.116209 | S12: =Raw_SRC_V16C_Repeats!H9 -> 0.80116209 | T12: =Raw_SRC_V16C_Repeats!I9*100 -> 85.333333 | U12: =Raw_SRC_V16C_Repeats!J9 -> 4000 | V12: =Raw_SRC_V16C_Repeats!K9 -> 64 | W12: =Raw_SRC_V16C_Repeats!L9 -> 0.95 | X12: =Raw_SRC_V16C_Repeats!M9 -> (0.01, 0.1, 1.0) | Y12: =Raw_SRC_V16C_Repeats!N9 -> 0.4 | Z12: =Raw_SRC_V16C_Repeats!O9 -> full | AA12: =Raw_SRC_V16C_Repeats!P9 -> grid_selected_by_val_only_no_test | AB12: =Raw_SRC_V16C_Repeats!R9 -> src_v16c_final_6datasets_repeat_rows.csv | AC12: =Raw_SRC_V16C_Repeats!S9 -> 49
A13: =Raw_SRC_V16C_Repeats!A10 -> amazon-computers | B13: ="SRC-v16c repeat "&Raw_SRC_V16C_Repeats!B10 -> SRC-v16c repeat 8 | C13: SRC-v16c | L13: =Raw_SRC_V16C_Repeats!B10 -> 8 | M13: =Raw_SRC_V16C_Repeats!C10 -> 20260427 | N13: =Raw_SRC_V16C_Repeats!D10 -> 0 | O13: =Raw_SRC_V16C_Repeats!E10 -> class_balanced_random_20_train_30_val_per_class | P13: =Raw_SRC_V16C_Repeats!F10*100 -> 100 | Q13: =Raw_SRC_V16C_Repeats!G10*100 -> 87.333333 | R13: =Raw_SRC_V16C_Repeats!H10*100 -> 77.210987 | S13: =Raw_SRC_V16C_Repeats!H10 -> 0.77210987 | T13: =Raw_SRC_V16C_Repeats!I10*100 -> 87.333333 | U13: =Raw_SRC_V16C_Repeats!J10 -> 4000 | V13: =Raw_SRC_V16C_Repeats!K10 -> 64 | W13: =Raw_SRC_V16C_Repeats!L10 -> 0.95 | X13: =Raw_SRC_V16C_Repeats!M10 -> (0.01, 0.1, 1.0) | Y13: =Raw_SRC_V16C_Repeats!N10 -> 0.6 | Z13: =Raw_SRC_V16C_Repeats!O10 -> full | AA13: =Raw_SRC_V16C_Repeats!P10 -> grid_selected_by_val_only_no_test | AB13: =Raw_SRC_V16C_Repeats!R10 -> src_v16c_final_6datasets_repeat_rows.csv | AC13: =Raw_SRC_V16C_Repeats!S10 -> 50
A14: =Raw_SRC_V16C_Repeats!A11 -> amazon-computers | B14: ="SRC-v16c repeat "&Raw_SRC_V16C_Repeats!B11 -> SRC-v16c repeat 9 | C14: SRC-v16c | L14: =Raw_SRC_V16C_Repeats!B11 -> 9 | M14: =Raw_SRC_V16C_Repeats!C11 -> 20260428 | N14: =Raw_SRC_V16C_Repeats!D11 -> 0 | O14: =Raw_SRC_V16C_Repeats!E11 -> class_balanced_random_20_train_30_val_per_class | P14: =Raw_SRC_V16C_Repeats!F11*100 -> 100 | Q14: =Raw_SRC_V16C_Repeats!G11*100 -> 83 | R14: =Raw_SRC_V16C_Repeats!H11*100 -> 77.837308 | S14: =Raw_SRC_V16C_Repeats!H11 -> 0.77837308 | T14: =Raw_SRC_V16C_Repeats!I11*100 -> 83 | U14: =Raw_SRC_V16C_Repeats!J11 -> 4000 | V14: =Raw_SRC_V16C_Repeats!K11 -> 64 | W14: =Raw_SRC_V16C_Repeats!L11 -> 0.95 | X14: =Raw_SRC_V16C_Repeats!M11 -> (0.01, 0.1, 1.0) | Y14: =Raw_SRC_V16C_Repeats!N11 -> 0.6 | Z14: =Raw_SRC_V16C_Repeats!O11 -> full | AA14: =Raw_SRC_V16C_Repeats!P11 -> grid_selected_by_val_only_no_test | AB14: =Raw_SRC_V16C_Repeats!R11 -> src_v16c_final_6datasets_repeat_rows.csv | AC14: =Raw_SRC_V16C_Repeats!S11 -> 51
A16: Dataset: amazon-photo
A17: amazon-photo | B17: Strongest baseline summary | C17: GraphSAGE | D17: =COUNT(Raw_Strongest_Baseline_Repeats!H12:H21) -> 10 | E17: =AVERAGE(Raw_Strongest_Baseline_Repeats!F12:F21)*100 -> 98.750001 | F17: =_xlfn.STDEV.S(Raw_Strongest_Baseline_Repeats!F12:F21)*100 -> 0.88388263 | G17: =AVERAGE(Raw_Strongest_Baseline_Repeats!G12:G21)*100 -> 91 | H17: =_xlfn.STDEV.S(Raw_Strongest_Baseline_Repeats!G12:G21)*100 -> 1.2453632 | I17: =AVERAGE(Raw_Strongest_Baseline_Repeats!H12:H21)*100 -> 87.586208 | J17: =_xlfn.STDEV.S(Raw_Strongest_Baseline_Repeats!H12:H21)*100 -> 1.3272796 | AB17: pyg_baselines_fair_best_by_val_partial(1)(1).csv | AC17: rows 12-21 in Raw_Strongest_Baseline_Repeats
A18: amazon-photo | B18: SRC-v16c summary | C18: SRC-v16c | D18: =COUNT(Raw_SRC_V16C_Repeats!H12:H21) -> 10 | E18: =AVERAGE(Raw_SRC_V16C_Repeats!F12:F21)*100 -> 100 | F18: =_xlfn.STDEV.S(Raw_SRC_V16C_Repeats!F12:F21)*100 -> 0 | G18: =AVERAGE(Raw_SRC_V16C_Repeats!G12:G21)*100 -> 91.666667 | H18: =_xlfn.STDEV.S(Raw_SRC_V16C_Repeats!G12:G21)*100 -> 2.2047928 | I18: =AVERAGE(Raw_SRC_V16C_Repeats!H12:H21)*100 -> 88.76 | J18: =_xlfn.STDEV.S(Raw_SRC_V16C_Repeats!H12:H21)*100 -> 1.3532785 | K18: =I18-I17 -> 1.173792 | AB18: SRC-v16c repeat rows: final 6-dataset package + chameleon CSV | AC18: Raw_SRC_V16C_Repeats rows 12-21
A19: =Raw_SRC_V16C_Repeats!A12 -> amazon-photo | B19: ="SRC-v16c repeat "&Raw_SRC_V16C_Repeats!B12 -> SRC-v16c repeat 0 | C19: SRC-v16c | L19: =Raw_SRC_V16C_Repeats!B12 -> 0 | M19: =Raw_SRC_V16C_Repeats!C12 -> 20260419 | N19: =Raw_SRC_V16C_Repeats!D12 -> 0 | O19: =Raw_SRC_V16C_Repeats!E12 -> class_balanced_random_20_train_30_val_per_class | P19: =Raw_SRC_V16C_Repeats!F12*100 -> 100 | Q19: =Raw_SRC_V16C_Repeats!G12*100 -> 92.5 | R19: =Raw_SRC_V16C_Repeats!H12*100 -> 88.675862 | S19: =Raw_SRC_V16C_Repeats!H12 -> 0.88675862 | T19: =Raw_SRC_V16C_Repeats!I12*100 -> 92.5 | U19: =Raw_SRC_V16C_Repeats!J12 -> 4000 | V19: =Raw_SRC_V16C_Repeats!K12 -> 32 | W19: =Raw_SRC_V16C_Repeats!L12 -> 0.9 | X19: =Raw_SRC_V16C_Repeats!M12 -> (0.01, 0.1, 1.0) | Y19: =Raw_SRC_V16C_Repeats!N12 -> 0.4 | Z19: =Raw_SRC_V16C_Repeats!O12 -> full | AA19: =Raw_SRC_V16C_Repeats!P12 -> grid_selected_by_val_only_no_test | AB19: =Raw_SRC_V16C_Repeats!R12 -> src_v16c_final_6datasets_repeat_rows.csv | AC19: =Raw_SRC_V16C_Repeats!S12 -> 32
A20: =Raw_SRC_V16C_Repeats!A13 -> amazon-photo | B20: ="SRC-v16c repeat "&Raw_SRC_V16C_Repeats!B13 -> SRC-v16c repeat 1 | C20: SRC-v16c | L20: =Raw_SRC_V16C_Repeats!B13 -> 1 | M20: =Raw_SRC_V16C_Repeats!C13 -> 20260420 | N20: =Raw_SRC_V16C_Repeats!D13 -> 0 | O20: =Raw_SRC_V16C_Repeats!E13 -> class_balanced_random_20_train_30_val_per_class | P20: =Raw_SRC_V16C_Repeats!F13*100 -> 100 | Q20: =Raw_SRC_V16C_Repeats!G13*100 -> 94.583333 | R20: =Raw_SRC_V16C_Repeats!H13*100 -> 88.97931 | S20: =Raw_SRC_V16C_Repeats!H13 -> 0.8897931 | T20: =Raw_SRC_V16C_Repeats!I13*100 -> 94.583333 | U20: =Raw_SRC_V16C_Repeats!J13 -> 4000 | V20: =Raw_SRC_V16C_Repeats!K13 -> 32 | W20: =Raw_SRC_V16C_Repeats!L13 -> 0.9 | X20: =Raw_SRC_V16C_Repeats!M13 -> (0.01, 0.1, 1.0) | Y20: =Raw_SRC_V16C_Repeats!N13 -> 0.7 | Z20: =Raw_SRC_V16C_Repeats!O13 -> full | AA20: =Raw_SRC_V16C_Repeats!P13 -> grid_selected_by_val_only_no_test | AB20: =Raw_SRC_V16C_Repeats!R13 -> src_v16c_final_6datasets_repeat_rows.csv | AC20: =Raw_SRC_V16C_Repeats!S13 -> 33
A21: =Raw_SRC_V16C_Repeats!A14 -> amazon-photo | B21: ="SRC-v16c repeat "&Raw_SRC_V16C_Repeats!B14 -> SRC-v16c repeat 2 | C21: SRC-v16c | L21: =Raw_SRC_V16C_Repeats!B14 -> 2 | M21: =Raw_SRC_V16C_Repeats!C14 -> 20260421 | N21: =Raw_SRC_V16C_Repeats!D14 -> 0 | O21: =Raw_SRC_V16C_Repeats!E14 -> class_balanced_random_20_train_30_val_per_class | P21: =Raw_SRC_V16C_Repeats!F14*100 -> 100 | Q21: =Raw_SRC_V16C_Repeats!G14*100 -> 90 | R21: =Raw_SRC_V16C_Repeats!H14*100 -> 85.682759 | S21: =Raw_SRC_V16C_Repeats!H14 -> 0.85682759 | T21: =Raw_SRC_V16C_Repeats!I14*100 -> 90 | U21: =Raw_SRC_V16C_Repeats!J14 -> 4000 | V21: =Raw_SRC_V16C_Repeats!K14 -> 32 | W21: =Raw_SRC_V16C_Repeats!L14 -> 0.9 | X21: =Raw_SRC_V16C_Repeats!M14 -> (0.05, 0.5, 5.0) | Y21: =Raw_SRC_V16C_Repeats!N14 -> 0.6 | Z21: =Raw_SRC_V16C_Repeats!O14 -> full | AA21: =Raw_SRC_V16C_Repeats!P14 -> grid_selected_by_val_only_no_test | AB21: =Raw_SRC_V16C_Repeats!R14 -> src_v16c_final_6datasets_repeat_rows.csv | AC21: =Raw_SRC_V16C_Repeats!S14 -> 34
A22: =Raw_SRC_V16C_Repeats!A15 -> amazon-photo | B22: ="SRC-v16c repeat "&Raw_SRC_V16C_Repeats!B15 -> SRC-v16c repeat 3 | C22: SRC-v16c | L22: =Raw_SRC_V16C_Repeats!B15 -> 3 | M22: =Raw_SRC_V16C_Repeats!C15 -> 20260422 | N22: =Raw_SRC_V16C_Repeats!D15 -> 0 | O22: =Raw_SRC_V16C_Repeats!E15 -> class_balanced_random_20_train_30_val_per_class | P22: =Raw_SRC_V16C_Repeats!F15*100 -> 100 | Q22: =Raw_SRC_V16C_Repeats!G15*100 -> 89.166667 | R22: =Raw_SRC_V16C_Repeats!H15*100 -> 89.958621 | S22: =Raw_SRC_V16C_Repeats!H15 -> 0.89958621 | T22: =Raw_SRC_V16C_Repeats!I15*100 -> 89.166667 | U22: =Raw_SRC_V16C_Repeats!J15 -> 4000 | V22: =Raw_SRC_V16C_Repeats!K15 -> 32 | W22: =Raw_SRC_V16C_Repeats!L15 -> 0.9 | X22: =Raw_SRC_V16C_Repeats!M15 -> (0.01, 0.1, 1.0) | Y22: =Raw_SRC_V16C_Repeats!N15 -> 0.8 | Z22: =Raw_SRC_V16C_Repeats!O15 -> full | AA22: =Raw_SRC_V16C_Repeats!P15 -> grid_selected_by_val_only_no_test | AB22: =Raw_SRC_V16C_Repeats!R15 -> src_v16c_final_6datasets_repeat_rows.csv | AC22: =Raw_SRC_V16C_Repeats!S15 -> 35
A23: =Raw_SRC_V16C_Repeats!A16 -> amazon-photo | B23: ="SRC-v16c repeat "&Raw_SRC_V16C_Repeats!B16 -> SRC-v16c repeat 4 | C23: SRC-v16c | L23: =Raw_SRC_V16C_Repeats!B16 -> 4 | M23: =Raw_SRC_V16C_Repeats!C16 -> 20260423 | N23: =Raw_SRC_V16C_Repeats!D16 -> 0 | O23: =Raw_SRC_V16C_Repeats!E16 -> class_balanced_random_20_train_30_val_per_class | P23: =Raw_SRC_V16C_Repeats!F16*100 -> 100 | Q23: =Raw_SRC_V16C_Repeats!G16*100 -> 91.25 | R23: =Raw_SRC_V16C_Repeats!H16*100 -> 89.489655 | S23: =Raw_SRC_V16C_Repeats!H16 -> 0.89489655 | T23: =Raw_SRC_V16C_Repeats!I16*100 -> 91.25 | U23: =Raw_SRC_V16C_Repeats!J16 -> 4000 | V23: =Raw_SRC_V16C_Repeats!K16 -> 32 | W23: =Raw_SRC_V16C_Repeats!L16 -> 0.9 | X23: =Raw_SRC_V16C_Repeats!M16 -> (0.1, 1.0, 10.0) | Y23: =Raw_SRC_V16C_Repeats!N16 -> 0.7 | Z23: =Raw_SRC_V16C_Repeats!O16 -> full | AA23: =Raw_SRC_V16C_Repeats!P16 -> grid_selected_by_val_only_no_test | AB23: =Raw_SRC_V16C_Repeats!R16 -> src_v16c_final_6datasets_repeat_rows.csv | AC23: =Raw_SRC_V16C_Repeats!S16 -> 36
A24: =Raw_SRC_V16C_Repeats!A17 -> amazon-photo | B24: ="SRC-v16c repeat "&Raw_SRC_V16C_Repeats!B17 -> SRC-v16c repeat 5 | C24: SRC-v16c | L24: =Raw_SRC_V16C_Repeats!B17 -> 5 | M24: =Raw_SRC_V16C_Repeats!C17 -> 20260424 | N24: =Raw_SRC_V16C_Repeats!D17 -> 0 | O24: =Raw_SRC_V16C_Repeats!E17 -> class_balanced_random_20_train_30_val_per_class | P24: =Raw_SRC_V16C_Repeats!F17*100 -> 100 | Q24: =Raw_SRC_V16C_Repeats!G17*100 -> 94.583333 | R24: =Raw_SRC_V16C_Repeats!H17*100 -> 89.475862 | S24: =Raw_SRC_V16C_Repeats!H17 -> 0.89475862 | T24: =Raw_SRC_V16C_Repeats!I17*100 -> 94.583333 | U24: =Raw_SRC_V16C_Repeats!J17 -> 5000 | V24: =Raw_SRC_V16C_Repeats!K17 -> 32 | W24: =Raw_SRC_V16C_Repeats!L17 -> 0.9 | X24: =Raw_SRC_V16C_Repeats!M17 -> (0.01, 0.1, 1.0) | Y24: =Raw_SRC_V16C_Repeats!N17 -> 0.6 | Z24: =Raw_SRC_V16C_Repeats!O17 -> full | AA24: =Raw_SRC_V16C_Repeats!P17 -> grid_selected_by_val_only_no_test | AB24: =Raw_SRC_V16C_Repeats!R17 -> src_v16c_final_6datasets_repeat_rows.csv | AC24: =Raw_SRC_V16C_Repeats!S17 -> 37
A25: =Raw_SRC_V16C_Repeats!A18 -> amazon-photo | B25: ="SRC-v16c repeat "&Raw_SRC_V16C_Repeats!B18 -> SRC-v16c repeat 6 | C25: SRC-v16c | L25: =Raw_SRC_V16C_Repeats!B18 -> 6 | M25: =Raw_SRC_V16C_Repeats!C18 -> 20260425 | N25: =Raw_SRC_V16C_Repeats!D18 -> 0 | O25: =Raw_SRC_V16C_Repeats!E18 -> class_balanced_random_20_train_30_val_per_class | P25: =Raw_SRC_V16C_Repeats!F18*100 -> 100 | Q25: =Raw_SRC_V16C_Repeats!G18*100 -> 89.166667 | R25: =Raw_SRC_V16C_Repeats!H18*100 -> 88.606897 | S25: =Raw_SRC_V16C_Repeats!H18 -> 0.88606897 | T25: =Raw_SRC_V16C_Repeats!I18*100 -> 89.166667 | U25: =Raw_SRC_V16C_Repeats!J18 -> 4000 | V25: =Raw_SRC_V16C_Repeats!K18 -> 32 | W25: =Raw_SRC_V16C_Repeats!L18 -> 0.9 | X25: =Raw_SRC_V16C_Repeats!M18 -> (0.01, 0.1, 1.0) | Y25: =Raw_SRC_V16C_Repeats!N18 -> 0.5 | Z25: =Raw_SRC_V16C_Repeats!O18 -> full | AA25: =Raw_SRC_V16C_Repeats!P18 -> grid_selected_by_val_only_no_test | AB25: =Raw_SRC_V16C_Repeats!R18 -> src_v16c_final_6datasets_repeat_rows.csv | AC25: =Raw_SRC_V16C_Repeats!S18 -> 38
A26: =Raw_SRC_V16C_Repeats!A19 -> amazon-photo | B26: ="SRC-v16c repeat "&Raw_SRC_V16C_Repeats!B19 -> SRC-v16c repeat 7 | C26: SRC-v16c | L26: =Raw_SRC_V16C_Repeats!B19 -> 7 | M26: =Raw_SRC_V16C_Repeats!C19 -> 20260426 | N26: =Raw_SRC_V16C_Repeats!D19 -> 0 | O26: =Raw_SRC_V16C_Repeats!E19 -> class_balanced_random_20_train_30_val_per_class | P26: =Raw_SRC_V16C_Repeats!F19*100 -> 100 | Q26: =Raw_SRC_V16C_Repeats!G19*100 -> 93.333333 | R26: =Raw_SRC_V16C_Repeats!H19*100 -> 87.806897 | S26: =Raw_SRC_V16C_Repeats!H19 -> 0.87806897 | T26: =Raw_SRC_V16C_Repeats!I19*100 -> 93.333333 | U26: =Raw_SRC_V16C_Repeats!J19 -> 4000 | V26: =Raw_SRC_V16C_Repeats!K19 -> 32 | W26: =Raw_SRC_V16C_Repeats!L19 -> 0.95 | X26: =Raw_SRC_V16C_Repeats!M19 -> (0.01, 0.1, 1.0) | Y26: =Raw_SRC_V16C_Repeats!N19 -> 0.3 | Z26: =Raw_SRC_V16C_Repeats!O19 -> full | AA26: =Raw_SRC_V16C_Repeats!P19 -> grid_selected_by_val_only_no_test | AB26: =Raw_SRC_V16C_Repeats!R19 -> src_v16c_final_6datasets_repeat_rows.csv | AC26: =Raw_SRC_V16C_Repeats!S19 -> 39
A27: =Raw_SRC_V16C_Repeats!A20 -> amazon-photo | B27: ="SRC-v16c repeat "&Raw_SRC_V16C_Repeats!B20 -> SRC-v16c repeat 8 | C27: SRC-v16c | L27: =Raw_SRC_V16C_Repeats!B20 -> 8 | M27: =Raw_SRC_V16C_Repeats!C20 -> 20260427 | N27: =Raw_SRC_V16C_Repeats!D20 -> 0 | O27: =Raw_SRC_V16C_Repeats!E20 -> class_balanced_random_20_train_30_val_per_class | P27: =Raw_SRC_V16C_Repeats!F20*100 -> 100 | Q27: =Raw_SRC_V16C_Repeats!G20*100 -> 92.916667 | R27: =Raw_SRC_V16C_Repeats!H20*100 -> 90.593103 | S27: =Raw_SRC_V16C_Repeats!H20 -> 0.90593103 | T27: =Raw_SRC_V16C_Repeats!I20*100 -> 92.916667 | U27: =Raw_SRC_V16C_Repeats!J20 -> 4000 | V27: =Raw_SRC_V16C_Repeats!K20 -> 32 | W27: =Raw_SRC_V16C_Repeats!L20 -> 0.9 | X27: =Raw_SRC_V16C_Repeats!M20 -> (0.01, 0.1, 1.0) | Y27: =Raw_SRC_V16C_Repeats!N20 -> 0.5 | Z27: =Raw_SRC_V16C_Repeats!O20 -> full | AA27: =Raw_SRC_V16C_Repeats!P20 -> grid_selected_by_val_only_no_test | AB27: =Raw_SRC_V16C_Repeats!R20 -> src_v16c_final_6datasets_repeat_rows.csv | AC27: =Raw_SRC_V16C_Repeats!S20 -> 40
A28: =Raw_SRC_V16C_Repeats!A21 -> amazon-photo | B28: ="SRC-v16c repeat "&Raw_SRC_V16C_Repeats!B21 -> SRC-v16c repeat 9 | C28: SRC-v16c | L28: =Raw_SRC_V16C_Repeats!B21 -> 9 | M28: =Raw_SRC_V16C_Repeats!C21 -> 20260428 | N28: =Raw_SRC_V16C_Repeats!D21 -> 0 | O28: =Raw_SRC_V16C_Repeats!E21 -> class_balanced_random_20_train_30_val_per_class | P28: =Raw_SRC_V16C_Repeats!F21*100 -> 100 | Q28: =Raw_SRC_V16C_Repeats!G21*100 -> 89.166667 | R28: =Raw_SRC_V16C_Repeats!H21*100 -> 88.331034 | S28: =Raw_SRC_V16C_Repeats!H21 -> 0.88331034 | T28: =Raw_SRC_V16C_Repeats!I21*100 -> 89.166667 | U28: =Raw_SRC_V16C_Repeats!J21 -> 5000 | V28: =Raw_SRC_V16C_Repeats!K21 -> 32 | W28: =Raw_SRC_V16C_Repeats!L21 -> 0.9 | X28: =Raw_SRC_V16C_Repeats!M21 -> (0.01, 0.1, 1.0) | Y28: =Raw_SRC_V16C_Repeats!N21 -> 0.4 | Z28: =Raw_SRC_V16C_Repeats!O21 -> full | AA28: =Raw_SRC_V16C_Repeats!P21 -> grid_selected_by_val_only_no_test | AB28: =Raw_SRC_V16C_Repeats!R21 -> src_v16c_final_6datasets_repeat_rows.csv | AC28: =Raw_SRC_V16C_Repeats!S21 -> 41
A30: Dataset: chameleon
A31: chameleon | B31: Strongest baseline summary | C31: LINKX | D31: =COUNT(Raw_Strongest_Baseline_Repeats!H22:H31) -> 10 | E31: =AVERAGE(Raw_Strongest_Baseline_Repeats!F22:F31)*100 -> 99.890109 | F31: =_xlfn.STDEV.S(Raw_Strongest_Baseline_Repeats!F22:F31)*100 -> 0.19688015 | G31: =AVERAGE(Raw_Strongest_Baseline_Repeats!G22:G31)*100 -> 72.551439 | H31: =_xlfn.STDEV.S(Raw_Strongest_Baseline_Repeats!G22:G31)*100 -> 1.5898134 | I31: =AVERAGE(Raw_Strongest_Baseline_Repeats!H22:H31)*100 -> 71.249999 | J31: =_xlfn.STDEV.S(Raw_Strongest_Baseline_Repeats!H22:H31)*100 -> 1.485375 | AB31: pyg_baselines_fair_best_by_val_partial(1)(1).csv | AC31: rows 22-31 in Raw_Strongest_Baseline_Repeats
A32: chameleon | B32: SRC-v16c summary | C32: SRC-v16c | D32: =COUNT(Raw_SRC_V16C_Repeats!H22:H31) -> 10 | E32: =AVERAGE(Raw_SRC_V16C_Repeats!F22:F31)*100 -> 97.75641 | F32: =_xlfn.STDEV.S(Raw_SRC_V16C_Repeats!F22:F31)*100 -> 1.622284 | G32: =AVERAGE(Raw_SRC_V16C_Repeats!G22:G31)*100 -> 72.798354 | H32: =_xlfn.STDEV.S(Raw_SRC_V16C_Repeats!G22:G31)*100 -> 2.2862826 | I32: =AVERAGE(Raw_SRC_V16C_Repeats!H22:H31)*100 -> 72.47807 | J32: =_xlfn.STDEV.S(Raw_SRC_V16C_Repeats!H22:H31)*100 -> 1.8528935 | K32: =I32-I31 -> 1.2280708 | AB32: SRC-v16c repeat rows: final 6-dataset package + chameleon CSV | AC32: Raw_SRC_V16C_Repeats rows 22-31
A33: =Raw_SRC_V16C_Repeats!A22 -> chameleon | B33: ="SRC-v16c repeat "&Raw_SRC_V16C_Repeats!B22 -> SRC-v16c repeat 0 | C33: SRC-v16c | L33: =Raw_SRC_V16C_Repeats!B22 -> 0 | M33: =Raw_SRC_V16C_Repeats!C22 -> 0 | N33: =Raw_SRC_V16C_Repeats!D22 -> 0 | O33: =Raw_SRC_V16C_Repeats!E22 -> fixed_geom_gcn_split_id_0 | P33: =Raw_SRC_V16C_Repeats!F22*100 -> 98.992674 | Q33: =Raw_SRC_V16C_Repeats!G22*100 -> 73.9369 | R33: =Raw_SRC_V16C_Repeats!H22*100 -> 72.587719 | S33: =Raw_SRC_V16C_Repeats!H22 -> 0.72587719 | T33: =Raw_SRC_V16C_Repeats!I22*100 -> 73.882027 | U33: =Raw_SRC_V16C_Repeats!J22 -> 8000 | V33: =Raw_SRC_V16C_Repeats!K22 -> 96 | W33: =Raw_SRC_V16C_Repeats!L22 -> 0.95 | X33: =Raw_SRC_V16C_Repeats!M22 -> (0.01, 0.1, 1.0) | Y33: =Raw_SRC_V16C_Repeats!N22 -> 0.6 | Z33: =Raw_SRC_V16C_Repeats!O22 -> full | AA33: =Raw_SRC_V16C_Repeats!P22 -> grid_selected_by_val_only_no_test | AB33: =Raw_SRC_V16C_Repeats!R22 -> src_v16c_main_table_10repeat_rows(1).csv | AC33: =Raw_SRC_V16C_Repeats!S22 -> 2
